from fastapi import FastAPI, Request
from fastapi.responses import JSONResponse
import logging
import time
import traceback

app = FastAPI()


logging.basicConfig(
    filename="app.log",
    format="%(asctime)s | %(levelname)s | %(message)s",
    level=logging.INFO
)

@app.on_event("startup")
async def startup_event():
    app.state.visit_count = 0  # Initialize visit count


@app.middleware("http")
async def count_visits(request: Request, call_next):
    app.state.visit_count += 1
    logging.info(f"ðŸ”¢ Visit number: {app.state.visit_count} - {request.method} {request.url.path}")
    response = await call_next(request)
    return response


@app.middleware("http")
async def log_requests(request: Request, call_next):
    start = time.time()
    try:
        response = await call_next(request)
    except Exception as e:
        duration = round(time.time() - start, 3)
        logging.error(
            f"Exception in {request.method} {request.url.path}: {str(e)}\n{traceback.format_exc()}"
        )
        raise e
    duration = round(time.time() - start, 3)
    logging.info(
        f"{request.method} {request.url.path} | Status: {response.status_code} | Duration: {duration}s"
    )
    return response


students = [{"id": 1, "name": "Rahul"}, {"id": 2, "name": "Neha"}]

@app.get("/students")
def get_students():
    return students

@app.get("/visits")
def get_visits():
    return {"visit_count": app.state.visit_count}

@app.get("/error-demo")
def error_demo():
    raise ValueError("Simulated error for testing logs")


@app.exception_handler(Exception)
async def global_exception_handler(request: Request, exc: Exception):
    logging.error(
        f"Unhandled error in {request.url.path}: {str(exc)}\n{traceback.format_exc()}"
    )
    return JSONResponse(
        status_code=500,
        content={"error": "Internal Server Error", "detail": str(exc)},
    )
